<?xml version="1.0" encoding="UTF-8"?>
<testng-results skipped="0" failed="2" total="2" passed="0">
  <reporter-output>
  </reporter-output>
  <suite name="Default suite" duration-ms="150" started-at="2018-05-20T17:31:33Z" finished-at="2018-05-20T17:31:33Z">
    <groups>
    </groups>
    <test name="Default test" duration-ms="150" started-at="2018-05-20T17:31:33Z" finished-at="2018-05-20T17:31:33Z">
      <class name="testNgTutorial.SoftAssertionDemo">
        <test-method status="FAIL" signature="hardAssert()[pri:0, instance:testNgTutorial.SoftAssertionDemo@2669b199]" name="hardAssert" duration-ms="17" started-at="2018-05-20T23:01:33Z" finished-at="2018-05-20T23:01:33Z">
          <exception class="java.lang.AssertionError">
            <message>
              <![CDATA[expected [13] but found [12]]]>
            </message>
            <full-stacktrace>
              <![CDATA[java.lang.AssertionError: expected [13] but found [12]
	at org.testng.Assert.fail(Assert.java:94)
	at org.testng.Assert.failNotEquals(Assert.java:496)
	at org.testng.Assert.assertEquals(Assert.java:125)
	at org.testng.Assert.assertEquals(Assert.java:372)
	at org.testng.Assert.assertEquals(Assert.java:382)
	at testNgTutorial.SoftAssertionDemo.hardAssert(SoftAssertionDemo.java:24)
	at sun.reflect.NativeMethodAccessorImpl.invoke0(Native Method)
	at sun.reflect.NativeMethodAccessorImpl.invoke(Unknown Source)
	at sun.reflect.DelegatingMethodAccessorImpl.invoke(Unknown Source)
	at java.lang.reflect.Method.invoke(Unknown Source)
	at org.testng.internal.MethodInvocationHelper.invokeMethod(MethodInvocationHelper.java:85)
	at org.testng.internal.Invoker.invokeMethod(Invoker.java:639)
	at org.testng.internal.Invoker.invokeTestMethod(Invoker.java:816)
	at org.testng.internal.Invoker.invokeTestMethods(Invoker.java:1124)
	at org.testng.internal.TestMethodWorker.invokeTestMethods(TestMethodWorker.java:125)
	at org.testng.internal.TestMethodWorker.run(TestMethodWorker.java:108)
	at org.testng.TestRunner.privateRun(TestRunner.java:774)
	at org.testng.TestRunner.run(TestRunner.java:624)
	at org.testng.SuiteRunner.runTest(SuiteRunner.java:359)
	at org.testng.SuiteRunner.runSequentially(SuiteRunner.java:354)
	at org.testng.SuiteRunner.privateRun(SuiteRunner.java:312)
	at org.testng.SuiteRunner.run(SuiteRunner.java:261)
	at org.testng.SuiteRunnerWorker.runSuite(SuiteRunnerWorker.java:52)
	at org.testng.SuiteRunnerWorker.run(SuiteRunnerWorker.java:86)
	at org.testng.TestNG.runSuitesSequentially(TestNG.java:1215)
	at org.testng.TestNG.runSuitesLocally(TestNG.java:1140)
	at org.testng.TestNG.run(TestNG.java:1048)
	at org.testng.remote.AbstractRemoteTestNG.run(AbstractRemoteTestNG.java:114)
	at org.testng.remote.RemoteTestNG.initAndRun(RemoteTestNG.java:251)
	at org.testng.remote.RemoteTestNG.main(RemoteTestNG.java:77)
]]>
            </full-stacktrace>
          </exception> <!-- java.lang.AssertionError -->
          <reporter-output>
          </reporter-output>
        </test-method> <!-- hardAssert -->
        <test-method status="FAIL" signature="testSoft()[pri:0, instance:testNgTutorial.SoftAssertionDemo@2669b199]" name="testSoft" duration-ms="26" started-at="2018-05-20T23:01:33Z" finished-at="2018-05-20T23:01:33Z">
          <exception class="java.lang.AssertionError">
            <message>
              <![CDATA[The following asserts failed:
	matched or not expected [13] but found [12]]]>
            </message>
            <full-stacktrace>
              <![CDATA[java.lang.AssertionError: The following asserts failed:
	matched or not expected [13] but found [12]
	at org.testng.asserts.SoftAssert.assertAll(SoftAssert.java:43)
	at testNgTutorial.SoftAssertionDemo.testSoft(SoftAssertionDemo.java:17)
	at sun.reflect.NativeMethodAccessorImpl.invoke0(Native Method)
	at sun.reflect.NativeMethodAccessorImpl.invoke(Unknown Source)
	at sun.reflect.DelegatingMethodAccessorImpl.invoke(Unknown Source)
	at java.lang.reflect.Method.invoke(Unknown Source)
	at org.testng.internal.MethodInvocationHelper.invokeMethod(MethodInvocationHelper.java:85)
	at org.testng.internal.Invoker.invokeMethod(Invoker.java:639)
	at org.testng.internal.Invoker.invokeTestMethod(Invoker.java:816)
	at org.testng.internal.Invoker.invokeTestMethods(Invoker.java:1124)
	at org.testng.internal.TestMethodWorker.invokeTestMethods(TestMethodWorker.java:125)
	at org.testng.internal.TestMethodWorker.run(TestMethodWorker.java:108)
	at org.testng.TestRunner.privateRun(TestRunner.java:774)
	at org.testng.TestRunner.run(TestRunner.java:624)
	at org.testng.SuiteRunner.runTest(SuiteRunner.java:359)
	at org.testng.SuiteRunner.runSequentially(SuiteRunner.java:354)
	at org.testng.SuiteRunner.privateRun(SuiteRunner.java:312)
	at org.testng.SuiteRunner.run(SuiteRunner.java:261)
	at org.testng.SuiteRunnerWorker.runSuite(SuiteRunnerWorker.java:52)
	at org.testng.SuiteRunnerWorker.run(SuiteRunnerWorker.java:86)
	at org.testng.TestNG.runSuitesSequentially(TestNG.java:1215)
	at org.testng.TestNG.runSuitesLocally(TestNG.java:1140)
	at org.testng.TestNG.run(TestNG.java:1048)
	at org.testng.remote.AbstractRemoteTestNG.run(AbstractRemoteTestNG.java:114)
	at org.testng.remote.RemoteTestNG.initAndRun(RemoteTestNG.java:251)
	at org.testng.remote.RemoteTestNG.main(RemoteTestNG.java:77)
]]>
            </full-stacktrace>
          </exception> <!-- java.lang.AssertionError -->
          <reporter-output>
          </reporter-output>
        </test-method> <!-- testSoft -->
      </class> <!-- testNgTutorial.SoftAssertionDemo -->
    </test> <!-- Default test -->
  </suite> <!-- Default suite -->
</testng-results>
